# Pytest CI/CD Diagnosis: Why CI Passes But Local Has 200+ Errors

## üîç The Problem

You're experiencing:
- **Local tests**: 200+ errors out of 811 tests
- **CI tests**: All passing

This is a **critical issue** because CI is giving you false confidence!

## üéØ Root Cause Analysis

### Test Discovery

Your project has **TWO test directories**:

1. **`backend/app/tests/`** - Main test directory
   - Contains: **50 test files**
   - Total tests: **811 tests**
   - Status: ‚ùå **200+ failures locally**

2. **`backend/tests/`** - Secondary/outdated directory
   - Contains: **1 test file** (`test_calendar_timezone.py`)
   - Total tests: **4 tests**
   - Status: ‚úÖ **All passing**

### CI Configuration

Looking at your workflows:

#### ‚úÖ **pytest.yml** - CORRECT
```yaml
python -m pytest app/tests/ \  # Runs all 811 tests
```

#### ‚úÖ **test-mysql.yml** - CORRECT
```yaml
python -m pytest app/tests/test_todo_attachment_endpoints.py  # Specific test
python -m pytest app/tests/  # All tests
```

**So CI IS configured correctly!** But why is it passing?

## üî¨ Possible Reasons CI Passes But Local Fails

### 1. **Test Database State**
- **CI**: Fresh MySQL container each run (clean state)
- **Local**: Possibly stale database with old data

### 2. **Environment Variables**
- **CI**: Uses `.env.test` configuration
- **Local**: Might use different `.env` or missing variables

### 3. **Dependencies**
- **CI**: Installs fresh from `requirements.txt`
- **Local**: Might have older/newer versions

### 4. **pytest.ini Configuration**
Your `pytest.ini` has:
```ini
--maxfail=3  # STOPS AFTER 3 FAILURES!
```

**This could be the issue!** If CI hits 3 failures, it stops but still reports some tests as "passed" because they never ran!

### 5. **Async Event Loop Issues**
```ini
asyncio_mode = auto
asyncio_default_fixture_loop_scope = function
```

Different Python/pytest-asyncio versions can behave differently.

### 6. **Test Fixtures**
Your `conftest.py` was recently modified. CI might be using cached or different fixture behavior.

## üõ†Ô∏è How to Diagnose

### Step 1: Check What CI Actually Ran

Download the pytest-output.log artifact from the last CI run:

1. Go to GitHub Actions
2. Find the latest pytest workflow run
3. Download "pytest-results" artifact
4. Check `pytest-output.log` - look for:
   - Total tests collected
   - How many passed/failed/skipped
   - If it stopped early due to `--maxfail=3`

### Step 2: Run Locally With CI Settings

```bash
cd backend

# Use exact CI pytest command
python -m pytest app/tests/ \
  --verbose \
  --tb=long \
  --strict-markers \
  --strict-config \
  --asyncio-mode=auto \
  --maxfail=5 \
  --durations=10
```

Remove `--maxfail` to see ALL failures:

```bash
python -m pytest app/tests/ -v --tb=short
```

### Step 3: Check Test Count

```bash
# How many tests does pytest collect?
cd backend
python -m pytest app/tests/ --collect-only | grep "test session starts" -A 1

# Should show: "collected 811 items"
```

### Step 4: Check For Skipped Tests

```bash
cd backend
python -m pytest app/tests/ -v | grep -E "SKIP|skip|XFAIL|xfail"
```

### Step 5: Check Database State

```bash
cd backend

# Clean database
docker-compose -f docker-compose.test.yml down -v
docker-compose -f docker-compose.test.yml up -d

# Wait for MySQL
sleep 30

# Run tests
python -m pytest app/tests/ -v
```

## üîß Solutions

### Solution 1: Remove --maxfail From CI

Update `.github/workflows/pytest.yml`:

```yaml
# BEFORE
--maxfail=5 \

# AFTER
# --maxfail=5 \  # Commented out to see all failures
```

This ensures ALL tests run, not just the first few.

### Solution 2: Add Test Count Verification

Add to pytest.yml before running tests:

```yaml
- name: Verify Test Collection
  working-directory: ./backend
  run: |
    COLLECTED=$(python -m pytest app/tests/ --collect-only -q 2>&1 | grep "test selected" | awk '{print $1}')
    echo "Collected $COLLECTED tests"
    if [ "$COLLECTED" -lt "800" ]; then
      echo "‚ö†Ô∏è Warning: Expected ~811 tests, got $COLLECTED"
    fi
```

### Solution 3: Add Failure Detection

Update pytest.yml to fail CI if there are test failures:

```yaml
- name: Run pytest with verbose output
  working-directory: ./backend
  continue-on-error: false  # Change from true
  id: pytest-run
  env:
    PYTHONPATH: .
    ENVIRONMENT: test
  run: |
    # ... existing command ...
    PYTEST_EXIT=$?
    if [ $PYTEST_EXIT -ne 0 ]; then
      echo "‚ùå Tests failed with exit code $PYTEST_EXIT"
      exit 1  # Actually fail the CI
    fi
```

### Solution 4: Match Local Environment to CI

Create `.env.test` locally:

```bash
cd backend
cat > .env.test << 'EOF'
ENVIRONMENT=test
SECRET_KEY=test-secret-key-for-pytest-ci-cd-testing
ALGORITHM=HS256
ACCESS_TOKEN_EXPIRE_MINUTES=30
DATABASE_URL=mysql+asyncmy://changeme:changeme@localhost:3307/miraiworks_test
REDIS_URL=redis://localhost:6379/0
SMTP_HOST=localhost
SMTP_PORT=587
SMTP_USER=test@example.com
SMTP_PASSWORD=testpassword
STORAGE_TYPE=local
STORAGE_PATH=/tmp/test_storage
CORS_ORIGINS=["http://localhost:3000"]
ALLOWED_HOSTS=["localhost", "127.0.0.1"]
DISABLE_AUTH_FOR_TESTS=false
MOCK_EXTERNAL_SERVICES=true
EOF

# Run tests with this config
ENVIRONMENT=test python -m pytest app/tests/ -v
```

### Solution 5: Add Comprehensive Test Report

The workflows I updated will now show you:
- Exact number of tests collected
- Number passed/failed/skipped
- Full test output

Check the artifacts after next CI run!

## üìä What To Check Next

1. **Download latest CI artifacts** - Check `pytest-output.log`
2. **Look for these patterns**:
   ```
   collected XXX items
   ===== XXX passed, YYY failed, ZZZ skipped in X.XXs =====
   ```
3. **Compare to local**:
   ```bash
   cd backend
   python -m pytest app/tests/ -v 2>&1 | tee local-test-results.txt
   # Check last lines for summary
   ```

## üö® Critical Action Items

### Immediate (Do This Now):

1. **Check actual CI test results**:
   ```bash
   # In your GitHub Actions, look at the pytest-run step
   # Scroll to the bottom - it should show:
   # "===== X passed, Y failed, Z skipped ====="
   ```

2. **Remove continue-on-error temporarily**:
   ```yaml
   # In .github/workflows/pytest.yml
   continue-on-error: false  # Make CI actually fail on test failures
   ```

3. **Check test count in CI logs**:
   - Should show "collected 811 items"
   - If it shows "collected 4 items" ‚Üí CI is running wrong directory!

### Short-term (Fix This Week):

1. **Remove or document `backend/tests/`** directory
   - If it's old, delete it
   - If it's needed, rename to avoid confusion

2. **Fix pytest.ini**:
   ```ini
   # Remove or increase maxfail
   --maxfail=50  # Allow more failures before stopping
   ```

3. **Add pre-commit hook** to run tests locally:
   ```bash
   #!/bin/bash
   cd backend
   python -m pytest app/tests/ --maxfail=5
   ```

## üìù Summary

**The Issue**: Your CI configuration looks correct, but something is causing it to report success despite local failures.

**Most Likely Causes**:
1. `--maxfail=3` stops testing after 3 failures (hides remaining failures)
2. `continue-on-error: true` in CI (doesn't fail the build)
3. Different database/environment state between local and CI
4. CI might be hitting timeout and reporting partial success

**Next Steps**:
1. Check latest CI logs/artifacts for actual test count
2. Remove `continue-on-error` to make CI fail properly
3. Match local environment to CI exactly
4. Run full test suite locally without `--maxfail`

**Expected Result After Fixes**:
- CI shows same ~200 failures as local
- You can then systematically fix all failing tests
- Both environments stay in sync

---

*Created: 2025-10-18*
*Status: Investigation needed - Check CI logs*
